Workbook
Name ___she1: #REF!
Name _housingandurbanaffairs: #REF!
Name _housingandurbanaffairs: #REF!
Name _housingandurbanaffairs: #REF!
Name _housingandurbanaffairs: #REF!
Name _housingandurbanaffairs: #REF!
Name _housingandurbanaffairs: #REF!
Name _housingandurbanaffairs: #REF!
Name _new2: #REF!
Name _new2: #REF!
Name _new2: #REF!
Name _new2: #REF!
Name _new2: #REF!
Name _new2: #REF!
Name _new2: #REF!
Name _she1: #REF!
Name _she1: #REF!
Name _she1: #REF!
Name _she1: #REF!
Name _she1: #REF!
Name _she1: #REF!
Name _she1: #REF!
Name AFLASAF_REV: #REF!
Name AFLASAF_REV: #REF!
Name AFLASAF_REV: #REF!
Name AFLASAF_REV: #REF!
Name AFLASAF_REV: #REF!
Name AFLASAF_REV: #REF!
Name AFLASAF_REV: #REF!
Name AFSC_REV: #REF!
Name AFSC_REV: #REF!
Name AFSC_REV: #REF!
Name AFSC_REV: #REF!
Name AFSC_REV: #REF!
Name AFSC_REV: #REF!
Name AFSC_REV: #REF!
Name Amend: #REF!
Name Amend: #REF!
Name Amend: #REF!
Name Amend: #REF!
Name Amend: #REF!
Name Amend: #REF!
Name AOC_REV: #REF!
Name AOC_REV: #REF!
Name AOC_REV: #REF!
Name AOC_REV: #REF!
Name AOC_REV: #REF!
Name AOC_REV: #REF!
Name ASD: #REF!
Name ASD: #REF!
Name ASD: #REF!
Name ASD: #REF!
Name ASD: #REF!
Name ASD: #REF!
Name ASFF_REV: #REF!
Name ASFF_REV: #REF!
Name ASFF_REV: #REF!
Name ASFF_REV: #REF!
Name ASFF_REV: #REF!
Name ASFF_REV: #REF!

Sheet COVER
A54: This document contains information licenced under the
A55: Open Government License - Alberta

Sheet Summary p1 st ops
A1: Summary Statement of Operations
A2: (millions of dollars)
B4: 2021-22 | C4: 2022-23 | E4: 2023-24 | F4: 2024-25 | G4: 2025-26
B5: Actual | C5: Budget | D5: Forecast | E5: Estimate | F5: Target | G5: Target
A7: Revenue
A8: Tax revenue | B8: 23506 | C8: 23034 | D8: 24580 | E8: 24992 | F8: 27055 | G8: 28609
A9: Non-renewable resource revenue | B9: 16170 | C9: 13840 | D9: 27544 | E9: 18361 | F9: 17284 | G9: 15742
A10: Federal transfers | B10: 11595 | C10: 12054 | D10: 11765 | E10: 12552 | F10: 12475 | G10: 13113
A11: Investment income | B11: 3579 | C11: 3173 | D11: 1035 | E11: 3154 | F11: 3273 | G11: 3407
A12: Other | B12: 13472 | C12: 10506 | D12: 11101 | E12: 11594 | F12: 11637 | G12: 11737
A13: Total Revenue | B13: 68322 | C13: 62607 | D13: 76025 | E13: 70653 | F13: 71724 | G13: 72608
A15: Expense
A16: Operating expense | B16: 52343 | C16: 51487 | D16: 55384 | E16: 57038 | F16: 58049 | G16: 59200
A17: Capital grants | B17: 2503 | C17: 2429 | D17: 1845 | E17: 2821 | F17: 3209 | G17: 3274
A18: Amortization / inventory consumption / loss on disposals | B18: 4186 | C18: 4057 | D18: 4480 | E18: 4397 | F18: 4460 | G18: 4509
A19: Debt servicing costs | B19: 2641 | C19: 2662 | D19: 2715 | E19: 2848 | F19: 2805 | G19: 3103
A20: Pension provisions | B20: -365 | C20: -289 | D20: -111 | E20: -322 | F20: -336 | G20: -347
A21: Contingency / disaster and emergency assistance / COVID-19 | B21: 3076 | C21: 1750 | D21: 1322 | E21: 1500 | F21: 1500 | G21: 1500
A22: Total Expense | B22: 64378 | C22: 62096 | D22: 65635 | E22: 68282 | F22: 69687 | G22: 71239
A24: Surplus / (deficit) | B24: 3944 | C24: 511 | D24: 10390 | E24: 2371 | F24: 2037 | G24: 1369

Sheet Summary p1 st finp
A1: Summary Statement of Financial Position
A2: (millions of dollars)
B4: At March 31
B5: 2022 | C5: 2023 | D5: 2024 | E5: 2025 | F5: 2026
B6: Actual | C6: Forecast | D6: Estimate | E6: Target | F6: Target
A8: Financial Assets | B8: 78126 | C8: 71533 | D8: 71851 | E8: 72782 | F8: 75506
A9: Liabilities | B9: 135092 | C9: 118902 | D9: 118356 | E9: 118375 | F9: 119612
A10: Net Financial Assets / (Debt) | B10: -56966 | C10: -47369 | D10: -46505 | E10: -45593 | F10: -44106
A11: Capital / Other Non-financial Assets | B11: 58576 | C11: 59549 | D11: 61197 | E11: 62362 | F11: 62244
A12: Deferred capital contributions | B12: -3523 | C12: -3703 | D12: -3844 | E12: -3884 | F12: -3884
A13: Net Assets | B13: -1913 | C13: 8477 | D13: 10848 | E13: 12885 | F13: 14254
A15: Net assets at the beginning of the year | B15: -5761 | C15: -1913 | D15: 8477 | E15: 10848 | F15: 12885
A16: Surplus / (Deficit) | B16: 3944 | C16: 10390 | D16: 2371 | E16: 2037 | F16: 1369
A17: Adjustment to net assets a | B17: -96 | C17: 0 | D17: 0 | E17: 0 | F17: 0
A19: Net assets at end of year | B19: -1913 | C19: 8477 | D19: 10848 | E19: 12885 | F19: 14254
A21: Net debt to GDP | B21: -0.152 | C21: -0.102 | D21: -0.102 | E21: -0.097 | F21: -0.091

Sheet Sch 1 Cons Fisc Sum
B1: Consolidated Fiscal Summary
B2: (millions of dollars)
B4: Statement of Operations | C4: 2021-22 | D4: 2022-23 | F4: 2023-24 | G4: 2024-25 | H4: 2025-26
C5: Actual | D5: Budget | E5: Forecast | F5: Estimate | G5: Target | H5: Target
A7: 1 | B7: Total Revenue | C7: 68322 | D7: 62607 | E7: 76025 | F7: 70653 | G7: 71724 | H7: 72608
B8: Expense
A9: 2 | B9: Operating expense | C9: 52343 | D9: 51487 | E9: 55384 | F9: 57038 | G9: 58049 | H9: 59200
A10: 3 | B10: % change from prior year | C10: 3.226379 | D10: -1.6353667 | E10: 5.8097549 | F10: 2.9864221 | G10: 1.7725025 | H10: 1.9828076
A11: 4 | B11: Capital grants | C11: 2503 | D11: 2429 | E11: 1845 | F11: 2821 | G11: 3209 | H11: 3274
A12: 5 | B12: Amortization / inventory consumption / loss on disposals | C12: 4186 | D12: 4057 | E12: 4480 | F12: 4397 | G12: 4460 | H12: 4509
A13: 6 | B13: Taxpayer-supported debt servicing costs | C13: 2278 | D13: 2443 | E13: 2217 | F13: 2097 | G13: 2156 | H13: 2513
A14: 7 | B14: Self-supported debt servicing costs | C14: 363 | D14: 219 | E14: 498 | F14: 751 | G14: 649 | H14: 590
A15: 8 | B15: Pension provisions | C15: -365 | D15: -289 | E15: -111 | F15: -322 | G15: -336 | H15: -347
A16: 9 | B16: Contingency / disaster and emergency assistance / COVID -19 | C16: 3076 | D16: 1750 | E16: 1322 | F16: 1500 | G16: 1500 | H16: 1500
A17: 10 | B17: Total Expense | C17: 64378 | D17: 62096 | E17: 65635 | F17: 68282 | G17: 69687 | H17: 71239
A19: 11 | B19: Surplus / (Deficit) | C19: 3944 | D19: 511 | E19: 10390 | F19: 2371 | G19: 2037 | H19: 1369
B21: Capital Plan
A23: 12 | B23: Capital grants | C23: 2503 | D23: 2429 | E23: 1845 | F23: 2821 | G23: 3209 | H23: 3274
A24: 13 | B24: Capital investment | C24: 4119 | D24: 5105 | E24: 4601 | F24: 5184 | G24: 4767 | H24: 3733
A26: 14 | B26: Total Capital Plan | C26: 6622 | D26: 7534 | E26: 6446 | F26: 8005 | G26: 7976 | H26: 7008
B28: Cash adjustments / borrowing requirements | C28: (at March 31)
A30: 15 | B30: Cash at start of year / Alberta Fund | C30: 7429 | D30: 7241 | E30: 8858 | F30: 3644 | G30: 1443 | H30: 0
A31: 16 | B31: Surplus / (deficit) | C31: 3944 | D31: 511 | E31: 10390 | F31: 2371 | G31: 2037 | H31: 1369
B32: Cash adjustments (for details, see table on page 209)
B33: Retained income of funds and agencies:
A34: 17 | B34: Alberta Heritage Savings Trust Fund | C34: -705 | D34: -494 | E34: -1813 | F34: -1096 | G34: -1324 | H34: -1494
A35: 18 | B35: Other fund and agencies | C35: -1236 | D35: -941 | E35: 120 | F35: -1629 | G35: -1528 | H35: -1720
A36: 19 | B36: Other cash adjustments | C36: -2268 | D36: 917 | E36: 1364 | F36: 2080 | G36: 1421 | H36: 1663
B37: Capital cash adjustments:
A38: 20 | B38: Capital investment (excl. SUCH self-financed; net of 10% contingency) | C38: -3492 | D38: -3547 | E38: -3139 | F38: -3759 | G38: -3428 | H38: -2516
A39: 21 | B39: Capital amortization (excluding SUCH; non-cash expense) | C39: 1118 | D39: 1304 | E39: 1249 | F39: 1302 | G39: 1360 | H39: 1400
A40: 22 | B40: Other capital cash adjustments | C40: -36 | D40: -7 | E40: -31 | F40: -28 | G40: -97 | H40: -103
A41: 23 | B41: Total cash available / (requirements) | C41: 4754 | D41: 4983 | E41: 16998 | F41: 2885 | G41: -116 | H41: -1401
A42: 24 | B42: Cash for debt repayment | C42: -708 | D42: -3207 | E42: -13354 | F42: -1442 | G42: 0 | H42: 0
A43: 25 | B43: Direct borrowing required | C43: 4812 | D43: 224 | E43: 0 | F43: 0 | G43: 116 | H43: 1401
A44: 26 | B44: Allocation to Alberta Fund | C44: 0 | D44: 0 | E44: 0 | F44: -1443 | G44: 0 | H44: 0
A45: 27 | B45: Cash at end of year | C45: 8858 | D45: 2000 | E45: 3644 | F45: 0 | G45: 0 | H45: 0
B47: Taxpayer-supported Liabilities / Borrowing | C47: (at March 31)
B49: Liabilities for Capital Projects
A50: 28 | B50: Opening balance | C50: 42733 | D50: 47381 | E50: 47529 | F50: 45828 | G50: 45815 | H50: 45849
...

Sheet Sch 2 Balance Sheet
A1: Balance Sheet Details
A2: (millions of dollars)
B4: At March 31
B5: 2022 | C5: 2023 | D5: 2024 | E5: 2025 | F5: 2026
B6: Actual | C6: Forecast | D6: Estimate | E6: Target | F6: Target
A7: Financial Assets
A8: Alberta Heritage Savings Trust Fund | B8: 17094 | C8: 18907 | D8: 20003 | E8: 21327 | F8: 22821
A9: Endowment funds:
A10: Alberta Heritage Foundation for Medical Research | B10: 2094 | C10: 2018 | D10: 2120 | E10: 2228 | F10: 2352
A11: Alberta Heritage Science and Engineering Research | B11: 1249 | C11: 1195 | D11: 1232 | E11: 1286 | F11: 1350
A12: Alberta Heritage Scholarship | B12: 1447 | C12: 1333 | D12: 1375 | E12: 1408 | F12: 1447
A13: Alberta Enterprise Corporation | B13: 292 | C13: 339 | D13: 335 | E13: 332 | F13: 329
A14: General Revenue Fund cash / Alberta Fund | B14: 8858 | C14: 3644 | D14: 1443 | E14: 0 | F14: 0
A15: Self-supporting lending organizations / activities:
A16: Local authority loans | B16: 14424 | C16: 14690 | D16: 14583 | E16: 14430 | F16: 14246
A17: Agriculture Financial Services Corporation | B17: 3967 | C17: 3864 | D17: 4833 | E17: 6033 | F17: 7373
A18: Equity in commercial enterprises | B18: 1766 | C18: 1898 | D18: 2300 | E18: 2393 | F18: 2628
A19: Student loans | B19: 3647 | C19: 4204 | D19: 4749 | E19: 5319 | F19: 5855
A20: Technology Innovation and Emissions Reduction Fund | B20: 337 | C20: 499 | D20: 533 | E20: 569 | F20: 558
A21: Other financial assets (including SUCH sector / Alberta Innovates Corp.) | B21: 22951 | C21: 18942 | D21: 18345 | E21: 17457 | F21: 16547
A22: Total Financial Assets | B22: 78126 | C22: 71533 | D22: 71851 | E22: 72782 | F22: 75506
A24: Liabilities
A25: Taxpayer-supported debt:
A26: Direct borrowing for the Capital Plan | B26: 44482 | C26: 42814 | D26: 42829 | E26: 42960 | F26: 44375
A27: Alternative financing (P3s - public-private partnerships - Capital Plan) | B27: 3047 | C27: 3014 | D27: 2986 | E27: 2889 | F27: 2786
A28: Debt issued to reduce pre-1992 TPP unfunded liability | B28: 594 | C28: 594 | D28: 594 | E28: 594 | F28: 594
A29: Direct borrowing for the Fiscal Plan | B29: 45001 | C29: 33315 | D29: 31883 | E29: 31893 | F29: 31903
A30: Total taxpayer-supported debt | B30: 93124 | C30: 79737 | D30: 78292 | E30: 78336 | F30: 79658
A31: Self-supporting lending organization / activities debt:
A32: Debt issued to finance local authority loans | B32: 14424 | C32: 14690 | D32: 14583 | E32: 14430 | F32: 14246
A33: Agriculture Financial Services Corporation | B33: 2604 | C33: 2772 | D33: 3077 | E33: 3207 | F33: 3337
A34: Total debt | B34: 110152 | C34: 97199 | D34: 95952 | E34: 95973 | F34: 97241
A36: Coal phase-out liabilities | B36: 761 | C36: 686 | D36: 609 | E36: 530 | F36: 448
A37: Pension liabilities | B37: 8271 | C37: 8160 | D37: 7838 | E37: 7502 | F37: 7155
A38: Other liabilities (including SUCH sector / Alberta Innovates Corp.) | B38: 15908 | C38: 12857 | D38: 13957 | E38: 14370 | F38: 14768
A39: Total Liabilities | B39: 135092 | C39: 118902 | D39: 118356 | E39: 118375 | F39: 119612
A40: Net Financial Assets / (Debt) | B40: -56966 | C40: -47369 | D40: -46505 | E40: -45593 | F40: -44106
A41: Capital / Other Non-financial Assets | B41: 58576 | C41: 59549 | D41: 61197 | E41: 62362 | F41: 62244
A42: Deferred capital contributions | B42: -3523 | C42: -3703 | D42: -3844 | E42: -3884 | F42: -3884
A43: Net Assets | B43: -1913 | C43: 8477 | D43: 10848 | E43: 12885 | F43: 14254
...

Sheet Sch 3 Capital assets
A1: Capital Assets
A2: (millions of dollars)
B4: At March 31
B5: 2022 | C5: 2023 | D5: 2024 | E5: 2025 | F5: 2026
B6: Actual | C6: Forecast | D6: Estimate | E6: Target | F6: Target
A8: Net book value at start of the year | B8: 55855 | C8: 57322 | D8: 58530 | E8: 60052 | F8: 61091
A9: Additions (capital investment) | B9: 4119 | C9: 4601 | D9: 5184 | E9: 4767 | F9: 3733
A10: 10% cash flow adjustment (rounded) | B10: 0 | C10: -650 | D10: -800 | E10: -800 | F10: -700
A11: Amortization | B11: -2586 | C11: -2741 | D11: -2862 | E11: -2928 | F11: -2941
A12: Net book value of capital asset disposals / adjustments | B12: -66 | C12: -2 | D12: 0 | E12: 0 | F12: 0
A13: Net Book Value at End of Year | B13: 57322 | C13: 58530 | D13: 60052 | E13: 61091 | F13: 61183

Sheet Sch 4 St of Ops
A1: Statement of Operations
A2: (millions of dollars)
B4: 2021-22 | C4: 2022-23 | E4: 2023-24 | F4: 2024-25 | G4: 2025-26
B5: Actual | C5: Budget | D5: Forecast | E5: Estimate | F5: Target | G5: Target
A7: Revenue
A8: Personal income tax | B8: 13335 | C8: 13382 | D8: 13806 | E8: 14069 | F8: 15034 | G8: 16071
A9: Corporate income tax | B9: 4718 | C9: 4040 | D9: 6413 | E9: 5911 | F9: 6254 | G9: 6590
A10: Other taxes | B10: 5453 | C10: 5612 | D10: 4361 | E10: 5012 | F10: 5767 | G10: 5948
A11: Non-renewable resource revenue | B11: 16170 | C11: 13840 | D11: 27544 | E11: 18361 | F11: 17284 | G11: 15742
A12: Transfers from Government of Canada | B12: 11595 | C12: 12054 | D12: 11765 | E12: 12552 | F12: 12475 | G12: 13113
A13: Investment income | B13: 3579 | C13: 3173 | D13: 1035 | E13: 3154 | F13: 3273 | G13: 3407
A14: Net income from govt. business enterprises | B14: 4810 | C14: 2435 | D14: 2449 | E14: 2727 | F14: 2422 | G14: 2647
A15: Premiums, fees and licences | B15: 4520 | C15: 4490 | D15: 4796 | E15: 5040 | F15: 5289 | G15: 5360
A16: Other | B16: 4142 | C16: 3581 | D16: 3856 | E16: 3827 | F16: 3926 | G16: 3730
A17: Total Revenue | B17: 68322 | C17: 62607 | D17: 76025 | E17: 70653 | F17: 71724 | G17: 72608
A19: Expense
A20: Advanced Education | B20: 5731 | C20: 6065 | D20: 6154 | E20: 6339 | F20: 6471 | G20: 6618
A21: Affordability and Utilities | B21: 380 | C21: 86 | D21: 740 | E21: 140 | F21: 92 | G21: 91
A22: Agriculture and Irrigation | B22: 3661 | C22: 793 | D22: 1919 | E22: 892 | F22: 909 | G22: 920
A23: Children's Services | B23: 1742 | C23: 2389 | D23: 2653 | E23: 2917 | F23: 2803 | G23: 3003
A24: Culture | B24: 214 | C24: 269 | D24: 269 | E24: 307 | F24: 257 | G24: 221
A25: Education | B25: 8541 | C25: 8883 | D25: 8956 | E25: 9317 | F25: 9525 | G25: 9651
A26: Energy | B26: 1793 | C26: 878 | D26: 1464 | E26: 984 | F26: 958 | G26: 1068
A27: Environment and Protected Areas | B27: 452 | C27: 449 | D27: 523 | E27: 554 | F27: 499 | G27: 357
A28: Executive Council | B28: 21 | C28: 25 | D28: 31 | E28: 35 | F28: 37 | G28: 38
A29: Forestry, Parks and Tourism | B29: 527 | C29: 427 | D29: 581 | E29: 435 | F29: 416 | G29: 408
A30: Health | B30: 24585 | C30: 23484 | D30: 25563 | E30: 26446 | F30: 27494 | G30: 27942
A31: Indigenous Relations | B31: 179 | C31: 184 | D31: 207 | E31: 230 | F31: 220 | G31: 220
... A56: Net assets at end of year | B56: -1913 | C56: -1402 | D56: 8477 | E56: 10848 | F56: 12885 | G56: 14254

Sheet Sch 5 Revenue
A1: Revenue (millions of dollars)
B3: 2021-22 | C3: 2022-23 | E3: 2023-24 | F3: 2024-25 | G3: 2025-26
B4: Actual | C4: Budget | D4: Forecast | E4: Estimate | F4: Target | G4: Target
A5: Income Taxes
A6: Personal income tax | B6: 13335 | C6: 13382 | D6: 13806 | E6: 14069 | F6: 15034 | G6: 16071
A7: Corporate income tax | B7: 4718 | C7: 4040 | D7: 6413 | E7: 5911 | F7: 6254 | G7: 6590
B8: 18053 | C8: 17422 | D8: 20219 | E8: 19980 | F8: 21288 | G8: 22661
A9: Other Taxes
A10: Education property tax (includes opted-out boards) | B10: 2478 | C10: 2504 | D10: 2504 | E10: 2504 | F10: 2604 | G10: 2703
A11: Fuel tax | B11: 1275 | C11: 1319 | D11: 134 | E11: 769 | F11: 1369 | G11: 1407
A12: Tobacco / vaping taxes | B12: 617 | C12: 644 | D12: 510 | E12: 489 | F12: 485 | G12: 463
A13: Insurance taxes | B13: 753 | C13: 819 | D13: 798 | E13: 851 | F13: 908 | G13: 969
A14: Cannabis tax | B14: 164 | C14: 157 | D14: 168 | E14: 173 | F14: 177 | G14: 181
A15: Tourism levy | B15: 59 | C15: 73 | D15: 95 | E15: 97 | F15: 105 | G15: 109
A16: Freehold mineral rights tax | B16: 107 | C16: 96 | D16: 152 | E16: 129 | F16: 119 | G16: 116
B17: 5453 | C17: 5612 | D17: 4361 | E17: 5012 | F17: 5767 | G17: 5948
A18: Non-Renewable Resource Revenue
A19: Bitumen royalty | B19: 11605 | C19: 10349 | D19: 18750 | E19: 12555 | F19: 12028 | G19: 10736
A20: Crude oil royalty | B20: 1947 | C20: 1670 | D20: 3965 | E20: 2905 | F20: 2633 | G20: 2442
A21: Natural gas and by-products royalty | B21: 2227 | C21: 1458 | D21: 4221 | E21: 2465 | F21: 2208 | G21: 2155
A22: Bonuses and sales of Crown leases | B22: 228 | C22: 236 | D22: 409 | E22: 307 | F22: 293 | G22: 289
A23: Rentals and fees / coal royalty | B23: 163 | C23: 127 | D23: 199 | E23: 129 | F23: 122 | G23: 120
B24: 16170 | C24: 13840 | D24: 27544 | E24: 18361 | F24: 17284 | G24: 15742
A25: Transfers from Government of Canada
A26: Canada Health Transfer | B26: 5503 | C26: 5352 | D26: 5520 | E26: 6079 | F26: 6287 | G26: 6708
A27: Canada Social Transfer | B27: 1796 | C27: 1868 | D27: 1864 | E27: 1942 | F27: 2022 | G27: 2102
A28: Direct transfers to SUCH sector / Alberta Innovates Corporation | B28: 478 | C28: 579 | D28: 624 | E28: 617 | F28: 623 | G28: 635
A29: Infrastructure support | B29: 808 | C29: 1293 | D29: 782 | E29: 935 | F29: 1166 | G29: 1083
A30: Agriculture support programs | B30: 531 | C30: 296 | D30: 491 | E30: 480 | F30: 517 | G30: 564
A31: Labour market agreements | B31: 485 | C31: 322 | D31: 324 | E31: 325 | F31: 325 | G31: 325
A32: Early learning child care agreements | B32: 197 | C32: 734 | D32: 734 | E32: 937 | F32: 1062 | G32: 1226
A33: Other (includes Fiscal Stabilization payment in 2023-24) | B33: 1797 | C33: 1610 | D33: 1426 | E33: 1237 | F33: 473 | G33: 470
B34: 11595 | C34: 12054 | D34: 11765 | E34: 12552 | F34: 12475 | G34: 13113
A35: Investment Income
A36: Alberta Heritage Savings Trust Fund | B36: 2128 | C36: 1976 | D36: -74 | E36: 1226 | F36: 1458 | G36: 1632
A37: Endowment funds | B37: 514 | C37: 440 | D37: -76 | E37: 352 | F37: 369 | G37: 401
A38: Income from local authority loans | B38: 329 | C38: 185 | D38: 450 | E38: 734 | F38: 612 | G38: 543
A39: Agriculture Financial Services Corporation | B39: 126 | C39: 113 | D39: 91 | E39: 126 | F39: 130 | G39: 139
A40: Other (includes SUCH sector) | B40: 482 | C40: 459 | D40: 644 | E40: 716 | F40: 704 | G40: 692
B41: 3579 | C41: 3173 | D41: 1035 | E41: 3154 | F41: 3273 | G41: 3407
...

Sheet Sch 6 Oper Exp
A1: Operating Expense
A2: (millions of dollars)
B4: 2021-22 | C4: 2022-23 | E4: 2023-24 | F4: 2024-25 | G4: 2025-26
B5: Actual | C5: Budget | D5: Forecast | E5: Estimate | F5: Target | G5: Target
A7: Advanced Education | B7: 5138 | C7: 5283 | D7: 5358 | E7: 5604 | F7: 5730 | G7: 5862
A8: Affordability and Utilities | B8: 356 | C8: 78 | D8: 732 | E8: 131 | F8: 84 | G8: 85
A9: Agriculture and Irrigation | B9: 665 | C9: 700 | D9: 710 | E9: 804 | F9: 801 | G9: 806
A10: Children's Services | B10: 1706 | C10: 2389 | D10: 2650 | E10: 2907 | F10: 2794 | G10: 2994
A11: Culture | B11: 161 | C11: 150 | D11: 162 | E11: 162 | F11: 163 | G11: 161
A12: Education | B12: 7846 | C12: 8390 | D12: 8456 | E12: 8836 | F12: 9036 | G12: 9162 | I12: =(E12-(D12+D37))/(D12+D37) -> 0.042349888
A13: Energy (incl. crude-by-rail expense of $866 million in 2021-22) | B13: 1419 | C13: 491 | D13: 782 | E13: 766 | F13: 740 | G13: 736 | I13: =G12-C12 -> 772 | K13: =G12-F12 -> 126 | L13: =F12-E12 -> 200 | M13: =E12-C12 -> 446
A14: Environment and Protected Areas | B14: 373 | C14: 364 | D14: 444 | E14: 497 | F14: 486 | G14: 344 | I14: =E12-D12-D37 -> 359
A15: Executive Council | B15: 21 | C15: 25 | D15: 31 | E15: 35 | F15: 37 | G15: 38 | I15: =D12+D37-C12-C37 -> 74
A16: Forestry, Parks and Tourism | B16: 311 | C16: 341 | D16: 344 | E16: 385 | F16: 369 | G16: 365
A17: Health | B17: 21238 | C17: 21917 | D17: 22585 | E17: 24533 | F17: 25443 | G17: 26041
A18: Indigenous Relations | B18: 153 | C18: 165 | D18: 175 | E18: 214 | F18: 212 | G18: 212
A19: Infrastructure | B19: 430 | C19: 408 | D19: 437 | E19: 462 | F19: 468 | G19: 466
A20: Jobs, Economy and Northern Development | B20: 197 | C20: 312 | D20: 300 | E20: 373 | F20: 354 | G20: 341
A21: Justice | B21: 459 | C21: 502 | D21: 594 | E21: 655 | F21: 659 | G21: 664
A22: Mental Health and Addiction | B22: 64 | C22: 101 | D22: 104 | E22: 148 | F22: 157 | G22: 191
A23: Municipal Affairs | B23: 187 | C23: 186 | D23: 185 | E23: 228 | F23: 230 | G23: 232
A24: Public Safety and Emergency Services | B24: 1060 | C24: 1024 | D24: 1051 | E24: 1187 | F24: 1216 | G24: 1209
A25: Seniors, Community and Social Services | B25: 4353 | C25: 4646 | D25: 4943 | E25: 5332 | F25: 5239 | G25: 5415
A26: Service Alberta and Red Tape Reduction | B26: 80 | C26: 88 | D26: 92 | E26: 112 | F26: 109 | G26: 104
A27: Skilled Trades and Professions | B27: 142 | C27: 162 | D27: 158 | E27: 175 | F27: 175 | G27: 176
... A32: Legislative Assembly | B32: 117 | C32: 170 | D32: 135 | E32: 178 | F32: 181 | G32: 184
A33: COVID-19 / Recovery Plan:
A34: Advanced Education | B34: 15 | C34: 62 | D34: 64 | E34: 0 | F34: 0 | G34: 0
A35: Children's Services | B35: 36 | C35: 0 | D35: 0 | E35: 0 | F35: 0 | G35: 0
A36: Culture | B36: 12 | C36: 0 | D36: 0 | E36: 0 | F36: 0 | G36: 0
A37: Education | B37: 130 | C37: 13 | D37: 21 | E37: 0 | F37: 0 | G37: 0
A38: Energy | B38: 318 | C38: 310 | D38: 600 | E38: 0 | F38: 0 | G38: 0
A39: Environment and Protected Areas | B39: 39 | C39: 27 | D39: 27 | E39: 0 | F39: 0 | G39: 0
A40: Forestry, Parks and Tourism | B40: 37 | C40: 22 | D40: 22 | E40: 0 | F40: 0 | G40: 0
A41: Health | B41: 1508 | C41: 10 | D41: 983 | E41: 0 | F41: 0 | G41: 0
A42: Infrastructure | B42: 6 | C42: 5 | D42: 5 | E42: 0 | F42: 0 | G42: 0
A43: Jobs, Economy and Northern Development | B43: 377 | C43: 106 | D43: 106 | E43: 0 | F43: 0 | G43: 0
A44: Mental Health and Addiction | B44: 20 | C44: 0 | D44: 0 | E44: 0 | F44: 0 | G44: 0
A45: Public Safety and Emergency Services | B45: 24 | C45: 0 | D45: 0 | E45: 0 | F45: 0 | G45: 0
... A51: Total Operating Expense | B51: 52343 | C51: 51487 | D51: 55384 | E51: 57038 | F51: 58049 | G51: 59200

Sheet Sch 7 Cap Amort
A1: Capital Amortization
A2: (millions of dollars)
B4: 2021-22 | C4: 2022-23 | E4: 2023-24 | F4: 2024-25 | G4: 2025-26
B5: Actual | C5: Budget | D5: Forecast | E5: Estimate | F5: Target | G5: Target
A7: Advanced Education | B7: 530 | C7: 557 | D7: 526 | E7: 556 | F7: 559 | G7: 570
A8: Affordability and Utilities | B8: 2 | C8: 2 | D8: 2 | E8: 2 | F8: 2 | G8: 2
A9: Agriculture and Irrigation | B9: 37 | C9: 49 | D9: 34 | E9: 36 | F9: 39 | G9: 41
A10: Children's Services | B10: 0 | C10: 0 | D10: 0 | E10: 1 | F10: 1 | G10: 1
A11: Culture | B11: 7 | C11: 8 | D11: 8 | E11: 8 | F11: 7 | G11: 7
A12: Education | B12: 471 | C12: 472 | D12: 469 | E12: 479 | F12: 488 | G12: 488
A13: Energy | B13: 14 | C13: 19 | D13: 14 | E13: 13 | F13: 13 | G13: 13
A14: Environment and Protected Areas | B14: 7 | C14: 15 | D14: 5 | E14: 4 | F14: 5 | G14: 5
A15: Forestry, Parks and Tourism | B15: 32 | C15: 56 | D15: 37 | E15: 38 | F15: 40 | G15: 41
A16: Health | B16: 472 | C16: 518 | D16: 518 | E16: 546 | F16: 542 | G16: 503
A17: Infrastructure | B17: 126 | C17: 151 | D17: 136 | E17: 146 | F17: 160 | G17: 169
A18: Jobs, Economy and Northern Development | B18: 2 | C18: 1 | D18: 1 | E18: 1 | F18: 1 | G18: 1
... A28: Total Amortization Expense | B28: 2586 | C28: 2839 | D28: 2741 | E28: 2862 | F28: 2928 | G28: 2941

Sheet Sch 8 Inv Consump
A1: Inventory Consumption
A2: (millions of dollars)
B4: 2021-22 | C4: 2022-23 | E4: 2023-24 | F4: 2024-25 | G4: 2025-26
B5: Actual | C5: Budget | D5: Forecast | E5: Estimate | F5: Target | G5: Target
A7: Advanced Education | B7: 48 | C7: 163 | D7: 205 | E7: 180 | F7: 183 | G7: 186
A8: Culture | B8: 0 | C8: 1 | D8: 1 | E8: 1 | F8: 1 | G8: 1
A9: Education | B9: 83 | C9: 0 | D9: 0 | E9: 0 | F9: 0 | G9: 0
A10: Forestry, Parks and Tourism | B10: 1 | C10: 1 | D10: 1 | E10: 1 | F10: 1 | G10: 1
A11: Health | B11: 1359 | C11: 988 | D11: 1465 | E11: 1278 | F11: 1269 | G11: 1297
A12: Infrastructure | B12: 2 | C12: 2 | D12: 2 | E12: 2 | F12: 2 | G12: 2
A13: Public Safety and Emergency Services | B13: 34 | C13: 0 | D13: 1 | E13: 1 | F13: 1 | G13: 1
A14: Service Alberta and Red Tape Reduction | B14: 4 | C14: 6 | D14: 6 | E14: 6 | F14: 6 | G14: 6
A15: Transportation and Economic Corridors | B15: 60 | C15: 57 | D15: 57 | E15: 62 | F15: 65 | G15: 66
A16: Total Inventory Consumption | B16: 1591 | C16: 1217 | D16: 1738 | E16: 1530 | F16: 1527 | G16: 1560

Sheet Sch 9 Inv Acquis
A1: Inventory Acquisition
A2: (millions of dollars)
B4: 2021-22 | C4: 2022-23 | E4: 2023-24 | F4: 2024-25 | G4: 2025-26
B5: Actual | C5: Budget | D5: Forecast | E5: Estimate | F5: Target | G5: Target
A6: Advanced Education | B6: 45 | C6: 181 | D6: 181 | E6: 181 | F6: 181 | G6: 181
A7: Culture | B7: 1 | C7: 1 | D7: 1 | E7: 1 | F7: 1 | G7: 1
A8: Education | B8: 79 | C8: 0 | D8: 0 | E8: 0 | F8: 0 | G8: 0
A9: Forestry, Parks and Tourism | B9: 1 | C9: 1 | D9: 1 | E9: 1 | F9: 1 | G9: 1
A10: Health | B10: 1257 | C10: 1148 | D10: 1293 | E10: 1404 | F10: 1398 | G10: 1094
A11: Infrastructure | B11: 2 | C11: 2 | D11: 2 | E11: 2 | F11: 2 | G11: 2
A12: Municipal Affairs | B12: 0 | C12: 0 | D12: 0 | E12: 0 | F12: 0 | G12: 0
A13: Public Safety and Emergency Services | B13: 2 | C13: 0 | D13: 1 | E13: 0 | F13: 0 | G13: 0
A14: Service Alberta and Red Tape Reduction | B14: 4 | C14: 6 | D14: 5 | E14: 6 | F14: 6 | G14: 6
A15: Transportation and Economic Corridors | B15: 54 | C15: 57 | D15: 57 | E15: 62 | F15: 65 | G15: 66
A16: Total Inventory Acquisition | B16: 1446 | C16: 1396 | D16: 1542 | E16: 1656 | F16: 1653 | G16: 1350

Sheet Sch 10 Debt Serv Costs
A1: Debt Servicing Costs
A2: (millions of dollars)
B4: 2021-22 | C4: 2022-23 | E4: 2023-24 | F4: 2024-25 | G4: 2025-26
B5: Actual | C5: Budget | D5: Forecast | E5: Estimate | F5: Target | G5: Target
A7: Taxpayer-supported general debt servicing costs
A8: Education – school boards | B8: 9 | C8: 9 | D8: 9 | E8: 9 | F8: 9 | G8: 9
A9: Treasury Board and Finance | B9: 1154 | C9: 1150 | D9: 940 | E9: 850 | F9: 797 | G9: 929
A10: Total | B10: 1163 | C10: 1159 | D10: 949 | E10: 859 | F10: 806 | G10: 938
A12: Taxpayer-supported Capital Plan debt servicing costs
A13: Education – Alberta Schools Alternative Procurement P3s | B13: 26 | C13: 25 | D13: 25 | E13: 24 | F13: 27 | G13: 27
A14: Transportation – ring road P3s | B14: 103 | C14: 103 | D14: 103 | E14: 101 | F14: 97 | G14: 94
A15: Treasury Board and Finance – direct borrowing | B15: 987 | C15: 1156 | D15: 1140 | E15: 1113 | F15: 1226 | G15: 1454
A16: Total | B16: 1116 | C16: 1284 | D16: 1268 | E16: 1238 | F16: 1350 | G16: 1575
A18: Total taxpayer-supported debt servicing costs | B18: 2278 | C18: 2443 | D18: 2217 | E18: 2097 | F18: 2156 | G18: 2513
A20: Self-supported debt servicing costs
A21: Treasury Board and Finance – for loans to local authorities | B21: 298 | C21: 155 | D21: 424 | E21: 659 | F21: 555 | G21: 493
A22: Treasury Board and Finance – Ag. Financial Services Corp. | B22: 65 | C22: 64 | D22: 74 | E22: 92 | F22: 94 | G22: 97
A23: Total | B23: 363 | C23: 219 | D23: 498 | E23: 751 | F23: 649 | G23: 590
A25: Total Debt Servicing Costs | B25: 2641 | C25: 2662 | D25: 2715 | E25: 2848 | F25: 2805 | G25: 3103

Sheet Sch 11 Disaster-emerg
A1: Contingency / Disaster and Emergency Assistance / COVID-19 / Recovery Plan
A2: (millions of dollars)
B4: 2021-22 | C4: 2022-23 | E4: 2023-24 | F4: 2024-25 | G4: 2025-26
B5: Actual | C5: Budget | D5: Forecast | E5: Estimate | F5: Target | G5: Target
A6: Agriculture and Irrigation – agric. support | B6: 2886 | C6: 0 | D6: 1131 | E6: 0 | F6: 0 | G6: 0
A7: Forestry, Parks and Tourism - wildfire fighting | B7: 144 | C7: 0 | D7: 173 | E7: 0 | F7: 0 | G7: 0
A8: Public Safety and Emergency Services – wildfire / flood support | B8: 32 | C8: 0 | D8: 18 | E8: 0 | F8: 0 | G8: 0
A9: Technology and Innovation – 1GX costs | B9: 14 | C9: 0 | D9: 0 | E9: 0 | F9: 0 | G9: 0
A10: Treasury Board and Fin. – disaster and emerg. assist. contingency | B10: 0 | C10: 1000 | D10: 0 | E10: 1500 | F10: 1500 | G10: 1500
A11: Treasury Board and Fin. – COVID-19 / Recovery Plan contingency | B11: 0 | C11: 750 | D11: 0 | E11: 0 | F11: 0 | G11: 0
A12: Total Contingency / Dis. & Emerg. Assist. / COVID-19 / Rec. Plan | B12: 3076 | C12: 1750 | D12: 1322 | E12: 1500 | F12: 1500 | G12: 1500

Sheet Sch 12 Pension Liab
A1: Pension Liabilities a
A2: (millions of dollars)
B3: At March 31
B4: 2022 | C4: 2023 | D4: 2024 | E4: 2025 | F4: 2026
B5: Actual | C5: Forecast | D5: Estimate | E5: Target | F5: Target
A6: Teachers' Pension Plan (pre-1992) | B6: 7244 | C6: 7208 | D6: 6943 | E6: 6668 | F6: 6385
A7: Public Service Management Pension Plan (pre-1992; closed) b | B7: 386 | C7: 354 | D7: 322 | E7: 288 | F7: 254
A8: Universities Academic Pension Plan (pre-1992) | B8: 226 | C8: 225 | D8: 225 | E8: 225 | F8: 225
A9: Special Forces Pension Plan (pre-1992) | B9: 85 | C9: 74 | D9: 76 | E9: 77 | F9: 75
A10: Members of the Legislative Assembly Pension Plan (closed) b | B10: 35 | C10: 33 | D10: 31 | E10: 28 | F10: 26
A11: Public Service Supplementary Retirement Plan | B11: 25 | C11: 24 | D11: 24 | E11: 24 | F11: 24
A12: Provincial Judges and Masters in Chambers Pension Plan | B12: 1 | C12: 1 | D12: 1 | E12: 1 | F12: 1
A13: SUCH sector – Universities Academic / Supp. Exec. Retirement Plans | B13: 269 | C13: 241 | D13: 216 | E13: 191 | F13: 165
A14: Total Pension Liabilities | B14: 8271 | C14: 8160 | D14: 7838 | E14: 7502 | F14: 7155
A15: Annual Non-cash Change in Pension Liabilities | B15: -365 | C15: -111 | D15: -322 | E15: -336 | F15: -347

Sheet Sch 13 Principal Repayments
A1: Annual Debt Maturities
A2: (millions of dollars)
B4: 2021-22 | C4: 2022-23 | D4: 2023-24 | E4: 2024-25 | F4: 2025-26 | G4: 2026-27
A5: Long-term debt maturities | B5: 4922 | C5: 5292 | D5: 7522 | E5: 5971 | F5: 13199 | G5: 5825
A6: Short-term debt maturities | B6: 0 | C6: 8062 | D6: 0 | E6: 0 | F6: 0 | G6: 0
A7: Total Annual Debt Maturities | B7: 4922 | C7: 13354 | D7: 7522 | E7: 5971 | F7: 13199 | G7: 5825

Sheet Sch 14 Cash Adjustm
A1: Cash Adjustmentsa
B3: 2021-22 | C3: 2022-23 | E3: 2023-24 | F3: 2024-25 | G3: 2025-26
B4: Actual | C4: Budget | D4: Forecast | E4: Estimate | F4: Target | G4: Target
A5: Retained Income of Funds and Agencies
A6: Alberta Heritage Savings Trust Fund | B6: -705 | C6: -494 | D6: -1813 | E6: -1096 | F6: -1324 | G6: -1494
A7: ATB Financial | B7: -586 | C7: -313 | D7: -282 | E7: -279 | F7: -324 | G7: -358
A8: Agriculture Financial Services Corporation | B8: 2074 | C8: -392 | D8: 243 | E8: -910 | F8: -1061 | G8: -1199
A9: Heritage Foundation for Medical Research Endowment Fund | B9: -153 | C9: -106 | D9: 76 | E9: -102 | F9: -108 | G9: -124
A10: Heritage Science and Engineering Research Endowment Fund | B10: -88 | C10: -81 | D10: 54 | E10: -37 | F10: -54 | G10: -64
A11: Heritage Scholarship Fund | B11: -87 | C11: -78 | D11: 114 | E11: -42 | F11: -33 | G11: -39
A12: Alberta Social Housing Corporation | B12: -3 | C12: -28 | D12: 9 | E12: -95 | F12: -141 | G12: -67
A13: Credit Union Deposit Guarantee Corporation | B13: -11 | C13: -15 | D13: -18 | E13: -13 | F13: -17 | G13: -17
A14: Alberta Petroleum Marketing Commission | B14: -2059 | C14: 329 | D14: 318 | E14: 18 | F14: 376 | G14: 263
A15: Technology Innovation and Emissions Reduction Fund | B15: -196 | C15: -75 | D15: -162 | E15: -34 | F15: -36 | G15: 11
A16: Balancing Pool | B16: -96 | C16: -112 | D16: -120 | E16: -103 | F16: -103 | G16: -103
A17: Other | B17: -31 | C17: -71 | D17: -112 | E17: -32 | F17: -27 | G17: -23
A18: Total Retained Income of Funds and Agencies | B18: -1941 | C18: -1435 | D18: -1693 | E18: -2725 | F18: -2852 | G18: -3214
A19: Other Cash Adjustments
A20: SUCH sector own-source revenue | B20: -4910 | C20: -4979 | D20: -5101 | E20: -5292 | F20: -5458 | G20: -5590
A21: SUCH sector own-source expense | B21: 5500 | C21: 6413 | D21: 6866 | E21: 7087 | F21: 7400 | G21: 7525
A22: Net deferred capital contribution cash adjustment | B22: 249 | C22: 118 | D22: 120 | E22: 81 | F22: -19 | G22: -60
A23: Energy royalties (difference between accrued revenue & cash) | B23: -2418 | C23: 430 | D23: 170 | E23: 545 | F23: 878 | G23: 804
A24: Student loans | B24: -271 | C24: -502 | D24: -557 | E24: -545 | F24: -570 | G24: -536
A25: Other cash adjustments | B25: -264 | C25: -129 | D25: -334 | E25: 95 | F25: -462 | G25: -132
A26: 2013 Alberta flood assistance revenue / expense | B26: -22 | C26: -12 | D26: -12 | E26: 375 | F26: 0 | G26: 0
A27: Wood Buffalo wildfire revenue / expense | B27: -20 | C27: -51 | D27: -37 | E27: 57 | F27: -4 | G27: 0
A28: Pension provisions (non-cash expense) | B28: -365 | C28: -289 | D28: -111 | E28: -322 | F28: -336 | G28: -347
A29: Inventory acquisition (excluding SUCH sector; non-cash expense) | B29: -148 | C29: -227 | D29: -248 | E29: -160 | F29: -166 | G29: -162
A30: Inventory consumption (excluding SUCH sector; non-cash expense) | B30: 401 | C30: 144 | D30: 608 | E30: 158 | F30: 159 | G30: 161
A31: Total Other Cash Adjustments | B31: -2268 | C31: 917 | D31: 1364 | E31: 2080 | F31: 1421 | G31: 1663
A32: Capital cash adjustments
A33: Capital investment (excluding SUCH sector self-financed) | B33: -3492 | C33: -4297 | D33: -3789 | E33: -4559 | F33: -4228 | G33: -3216
A34: Capital Plan contingency | B34: 0 | C34: 750 | D34: 650 | E34: 800 | F34: 800 | G34: 700
A35: Current principal repayments (P3s – public-private partnerships) | B35: -83 | C35: -89 | D35: -89 | E35: -92 | F35: -98 | G35: -103
A36: Alternative financing (P3s – public-private partnerships) | B36: 43 | C36: 81 | D36: 56 | E36: 64 | F36: 1 | G36: 0
A37: Amortization (excluding SUCH sector; non-cash expense) | B37: 1118 | C37: 1304 | D37: 1249 | E37: 1302 | F37: 1360 | G37: 1400
A38: Book value of asset disposals (net non-cash expense / revenue) | B38: 4 | C38: 1 | D38: 2 | E38: 0 | F38: 0 | G38: 0
A39: Total Capital Cash Adjustments | B39: -2410 | C39: -2250 | D39: -1921 | E39: -2485 | F39: -2165 | G39: -1219

Sheet Sch 15 Capital Plan
A1: Capital Plana
A2: (millions of dollars)
B4: 2021-22 | C4: 2022-23 | E4: 2023-24 | F4: 2024-25 | G4: 2025-26
B5: Actual | C5: Budget | D5: Forecast | E5: Estimate | F5: Target | G5: Target
A6: Advanced Education | B6: 583 | C6: 616 | D6: 617 | E6: 492 | F6: 394 | G6: 326
A7: Affordability and Utilities | B7: 22 | C7: 8 | D7: 8 | E7: 7 | F7: 7 | G7: 5
A8: Agriculture and Irrigation | B8: 77 | C8: 51 | D8: 49 | E8: 64 | F8: 76 | G8: 80
A9: Children's Services | B9: 0 | C9: 9 | D9: 18 | E9: 19 | F9: 18 | G9: 13
A10: Culture | B10: 35 | C10: 112 | D10: 99 | E10: 138 | F10: 88 | G10: 54
A11: Education | B11: 758 | C11: 937 | D11: 753 | E11: 765 | F11: 797 | G11: 627
A12: Energy | B12: 56 | C12: 73 | D12: 79 | E12: 221 | F12: 220 | G12: 334
A13: Environment and Protected Areas | B13: 43 | C13: 91 | D13: 77 | E13: 112 | F13: 36 | G13: 19
A14: Forestry, Parks and Tourism | B14: 62 | C14: 62 | D14: 65 | E14: 96 | F14: 112 | G14: 55
A15: Health | B15: 921 | C15: 1296 | D15: 989 | E15: 1273 | F15: 1624 | G15: 1330
A16: Indigenous Relations | B16: 26 | C16: 19 | D16: 32 | E16: 16 | F16: 8 | G16: 8
A17: Infrastructure | B17: 221 | C17: 402 | D17: 357 | E17: 423 | F17: 392 | G17: 302
... A29: Total Capital Plan | B29: 6622 | C29: 7534 | D29: 6446 | E29: 8005 | F29: 7976 | G29: 7008

Sheet Sch 16 Capital grants
A1: Capital Grants
A2: (millions of dollars)
B4: 2021-22 | C4: 2022-23 | E4: 2023-24 | F4: 2024-25 | G4: 2025-26
B5: Actual | C5: Budget | D5: Forecast | E5: Estimate | F5: Target | G5: Target
A7: Affordability and Utilities | B7: 22 | C7: 6 | D7: 6 | E7: 7 | F7: 6 | G7: 4
A8: Agriculture and Irrigation | B8: 73 | C8: 44 | D8: 44 | E8: 52 | F8: 70 | G8: 73
A9: Children's Services | B9: 0 | C9: 1 | D9: 3 | E9: 9 | F9: 8 | G9: 8
A10: Culture | B10: 34 | C10: 110 | D10: 98 | E10: 136 | F10: 86 | G10: 52
A11: Education | B11: 11 | C11: 8 | D11: 10 | E11: 3 | F11: 0 | G11: 1
A12: Energy | B12: 43 | C12: 58 | D12: 69 | E12: 205 | F12: 205 | G12: 319
A13: Environment and Protected Areas | B13: 33 | C13: 43 | D13: 48 | E13: 52 | F13: 9 | G13: 9
A14: Forestry, Parks and Tourism | B14: 2 | C14: 7 | D14: 4 | E14: 11 | F14: 6 | G14: 1
A15: Health | B15: 4 | C15: 51 | D15: 12 | E15: 89 | F15: 240 | G15: 100
A16: Indigenous Relations | B16: 26 | C16: 19 | D16: 32 | E16: 16 | F16: 8 | G16: 8
A17: Infrastructure | B17: 10 | C17: 16 | D17: 0 | E17: 3 | F17: 0 | G17: 0
A18: Mental Health and Addiction | B18: 1 | C18: 0 | D18: 10 | E18: 18 | F18: 15 | G18: 0
... A23: Total Capital Grants | B23: 2503 | C23: 2429 | D23: 1845 | E23: 2821 | F23: 3209 | G23: 3274

Sheet Sch 17 Capital Invest
A1: Capital Investment
A2: (millions of dollars)
B4: 2021-22 | C4: 2022-23 | E4: 2023-24 | F4: 2024-25 | G4: 2025-26
B5: Actual | C5: Budget | D5: Forecast | E5: Estimate | F5: Target | G5: Target
A7: Advanced Education | B7: 583 | C7: 616 | D7: 617 | E7: 492 | F7: 394 | G7: 326
A8: Affordability and Utilities | B8: 0 | C8: 2 | D8: 2 | E8: 1 | F8: 1 | G8: 1
A9: Agriculture and Irrigation | B9: 4 | C9: 7 | D9: 5 | E9: 11 | F9: 7 | G9: 7
A10: Children's Services | B10: 0 | C10: 8 | D10: 15 | E10: 10 | F10: 10 | G10: 5
A11: Culture | B11: 1 | C11: 2 | D11: 1 | E11: 2 | F11: 2 | G11: 2
A12: Education | B12: 747 | C12: 929 | D12: 743 | E12: 762 | F12: 797 | G12: 626
A13: Energy | B13: 13 | C13: 15 | D13: 10 | E13: 16 | F13: 15 | G13: 15
A14: Environment and Protected Areas | B14: 10 | C14: 48 | D14: 29 | E14: 59 | F14: 28 | G14: 11
A15: Forestry, Parks and Tourism | B15: 60 | C15: 55 | D15: 61 | E15: 85 | F15: 106 | G15: 54
A16: Health | B16: 917 | C16: 1245 | D16: 977 | E16: 1184 | F16: 1384 | G16: 1230
A17: Infrastructure | B17: 211 | C17: 386 | D17: 357 | E17: 420 | F17: 392 | G17: 302
A18: Jobs, Economy and Northern Development | B18: 1 | C18: 4 | D18: 4 | E18: 2 | F18: 1 | G18: 1
... A29: Total Capital Investment | B29: 4119 | C29: 5105 | D29: 4601 | E29: 5184 | F29: 4767 | G29: 3733

Sheet Sch 18 Capital Plan Funding
A1: Capital Plan Funding Sources
A2: (millions of dollars)
B4: 2021-22 | C4: 2022-23 | E4: 2023-24 | F4: 2024-25 | G4: 2025-26
B5: Actual | C5: Budget | D5: Forecast | E5: Estimate | F5: Target | G5: Target
A7: Capital Plan, less | B7: 6622 | C7: 7534 | D7: 6446 | E7: 8005 | F7: 7976 | G7: 7008
A8: 10% cash flow adjustment (rounded) | B8: 0 | C8: -750 | D8: -650 | E8: -800 | F8: -800 | G8: -700
A9: Capital Plan funding requirements | B9: 6622 | C9: 6784 | D9: 5796 | E9: 7205 | F9: 7176 | G9: 6308
A11: Source of funding:
A12: Cash received (primarily federal govt.) / donations / disposals | B12: 1065 | C12: 1455 | D12: 921 | E12: 1031 | F12: 1170 | G12: 1048
A13: Retained income of funds and agencies (primarily ASHC) | B13: 33 | C13: 35 | D13: 110 | E13: 35 | F13: 74 | G13: 102
A14: SUCH sector self-financed | B14: 627 | C14: 808 | D14: 812 | E14: 625 | F14: 539 | G14: 517
A15: TIER Fund | B15: 46 | C15: 66 | D15: 66 | E15: 63 | F15: 58 | G15: 129
A16: Alternative financing (P3s – public-private partnerships) | B16: 43 | C16: 81 | D16: 56 | E16: 64 | F16: 1 | G16: 0
A17: GRF cash / direct borrowing | B17: 4812 | C17: 4339 | D17: 3831 | E17: 5387 | F17: 5334 | G17: 4512
A18: Total Capital Plan Funding Sources | B18: 6622 | C18: 6784 | D18: 5796 | E18: 7205 | F18: 7177 | G18: 6308

Sheet Sch 19 Financing Reqt
A1: Borrowing Requirements
A2: (millions of dollars)
B3: 2021-22 | C3: 2022-23 | E3: 2023-24 | F3: 2024-25 | G3: 2025-26
B4: Actual | C4: Budget | D4: Forecast | E4: Estimate | F4: Target | G4: Target
A5: Taxpayer-supported debt | B5: 8667 | C5: 2249 | D5: 0 | E5: 5464 | F5: 5776 | G5: 14443
A6: Self-supported debt | B6: 319 | C6: 226 | D6: 2251 | E6: 469 | F6: 250 | G6: 250
A7: Government business enterprises | B7: 0 | C7: 1003 | D7: 1003 | E7: 733 | F7: 39 | G7: 350
A8: Total Borrowing Requirements | B8: 8986 | C8: 3478 | D8: 3254 | E8: 6666 | F8: 6065 | G8: 15043

Sheet Sch 20 Borrowing sources
A1: Borrowing Sources
A2: (millions of dollars)
B3: 2021-22 | C3: 2022-23 | E3: 2023-24 | F3: 2024-25 | G3: 2025-26
B4: Actual | C4: Budget | D4: Forecast | E4: Estimate | F4: Target | G4: Target
A5: Money market (net change) | B5: 4059 | C5: 782 | D5: 782 | E5: 0 | F5: 0 | G5: 4000
A6: Public-private partnerships (P3s) | B6: 43 | C6: 81 | D6: 56 | E6: 64 | F6: 1 | G6: 0
A7: Term debt | B7: 4884 | C7: 2615 | D7: 2416 | E7: 6602 | F7: 6064 | G7: 11043
A8: Total Borrowing Sources | B8: 8986 | C8: 3478 | D8: 3254 | E8: 6666 | F8: 6065 | G8: 15043

Sheet Sch 21 Alloc net gam lott rev
A1: Allocation of 2023-24 net gaming / lottery revenue
A2: (thousands of dollars)
A3: Net gaming / lottery revenue | B3: 1514605
A4: Agriculture and Irrigation | D4: Indigenous Relations
A5: Primary Agriculture | B5: 11896 | D5: First Nations and Métis Relations | E5: 147250
A6: Rural programming and Agricultural Societies | B6: 13962 | D6: First Nations Development Fund | E6: 200
A8: Culture | D8: Jobs, Economy and Northern Development
A9: Assistance - Alberta Foundation for Arts | B9: 25585 | D9: Skills and Training Support | E9: 400
A10: Assistance - Provincial Heritage Organizations | B10: 1705
A11: Assistance - Sport, Phys. Activity and Recreat. | B11: 22605 | D11: Seniors, Community and Social Services
A12: Community Facility Enhancement Program | B12: 50000 | D12: Family and Community Support Services | E12: 52000
A13: Community Initiatives Program | B13: 20025 | D13: Family and Community Safety | E13: 6500
A14: Heritage Preservation Partnership | B14: 1450 | D14: Fetal Alcohol Spectrum Disorder Initiatives | E14: 12000
A15: Other Initiatives | B15: 1000
D16: Trade, Immigration and Multiculturalism
A17: Education | D17: Settlement and Integration | E17: 4574
A18: Operations and Maintenance | B18: 150000
A19: Transportation | B19: 150000 | D19: Transportation
D20: Provincial Highway Maintenance | E20: 40000
A21: Environment and Protected Areas
A22: Resource Management | B22: 500 | D22: Treasury Board and Finance
D23: Airport Entertainment Centres | E23: 1000
A24: Health | D24: Gaming Research | E24: 1600
A25: Continuing Care | B25: 756603 | D25: Horse Racing and Breeding Renewal Program | E25: 43750
D26: Total Allocation | E26: 1514605

Sheet Sch 22 FTEs p16
A1: Full-Time Equivalents a
B2: 2022-23 | C2: 2023-24
B3: Budget | C3: Estimate | D3: Change
A4: Departments
A5: Advanced Education | B5: 281 | C5: 291 | D5: 10
A6: Affordability and Utilities | B6: 75 | C6: 86 | D6: 11
A7: Agriculture and Irrigation | B7: 622 | C7: 625 | D7: 3
A8: Children's Services | B8: 3015 | C8: 3026 | D8: 11
A9: Culture | B9: 498 | C9: 499 | D9: 1
A10: Education | B10: 507 | C10: 566 | D10: 59
A11: Energy | B11: 448 | C11: 451 | D11: 3
A12: Environment and Protected Areas | B12: 1221 | C12: 1219 | D12: -2
A13: Executive Council | B13: 150 | C13: 162 | D13: 12
A14: Forestry, Parks and Tourism | B14: 1562 | C14: 1666 | D14: 104
A15: Health | B15: 802 | C15: 850 | D15: 48
A16: Indigenous Relations | B16: 175 | C16: 176 | D16: 1
... A32: Departments | B32: 25981 | C32: 27572 | D32: 1591
A34: Agencies / SUCH sector / other operationally-independent entities
A35: Advanced Education – post-secondary institutions | B35: 32140 | C35: 32403 | D35: 263
A36: Affordability and Utilities – Alberta Utilities Commission | B36: 132 | C36: 132 | D36: 0
A37: Agriculture and Irrigation – Agriculture Financial Services Corporation | B37: 561 | C37: 570 | D37: 9
A38: Education – school boards (including Francophone / charter) | D38: 0
A39: Certificated Staff | B39: 37038 | C39: 37688 | D39: 650
A40: Non-certificated Staff | B40: 26026 | C40: 27401 | D40: 1375
A41: Energy – Alberta Energy Regulator | B41: 1048 | C41: 1048 | D41: 0
A42: Energy – Canadian Energy Centre | B42: 10 | C42: 10 | D42: 0
A43: Environment and Protected Areas – Natural Resources Conservation Board | B43: 34 | C43: 34 | D43: 0
A44: Forestry, Parks and Tourism – Travel Alberta Corporation | B44: 80 | C44: 80 | D44: 0
A45: Health – Alberta Health Services | B45: 84360 | C45: 87930 | D45: 3570
A46: Health – Health Quality Council of Alberta | B46: 36 | C46: 45 | D46: 9
A47: Indigenous Relations – Alberta Indigenous Opportunities Corporation | B47: 15 | C47: 15 | D47: 0
A48: Municipal Affairs – Safety Codes Council | B48: 60 | C48: 60 | D48: 0
A49: Public Safety and Emergency Services – Victims of Crime and Public Safety Fund | B49: 54 | C49: 54 | D49: 0
A50: Technology and Innovation – Alberta Enterprise Corporation | B50: 11 | C50: 12 | D50: 1
... A60: Total Full-Time Equivalents | B60: 210183 | C60: 217784 | D60: 7601

Sheet Sch 23 Exp by Object
A1: Ministry Expense by Object
B3: Salaries, Wages and Employee Benefits | C3: Supplies and Services | D3: Grants to Others | E3: Capital Grants | F3: Amortization of Capital Assets | G3: Consumption of Inventory | H3: Pension Provisions | I3: Debt Servicing Costs | J3: Other / contingency and disaster assistance | K3: Total 2023-24 Expense
A14: Legislative Assembly | B14: 88 | C14: 74 | D14: 0 | E14: 0 | F14: 2 | G14: 0 | H14: 0 | I14: 0 | J14: 16 | K14: 180
A16: Advanced Education | B16: 3734 | C16: 1294 | D16: 475 | E16: 0 | F16: 556 | G16: 180 | H16: -25 | I16: 0 | J16: 101 | K16: 6314
A17: Affordability and Utilities | B17: 36 | C17: 14 | D17: 62 | E17: 7 | F17: 2 | G17: 0 | H17: 0 | I17: 0 | J17: 19 | K17: 140
A18: Agriculture and Irrigation | B18: 125 | C18: 558 | D18: 112 | E18: 52 | F18: 36 | G18: 0 | H18: 0 | I18: 0 | J18: 9 | K18: 892
A19: Children's Services | B19: 339 | C19: 650 | D19: 1919 | E19: 9 | F19: 1 | G19: 0 | H19: 0 | I19: 0 | J19: 0 | K19: 2917
A20: Culture | B20: 55 | C20: 22 | D20: 83 | E20: 136 | F20: 8 | G20: 1 | H20: 0 | I20: 0 | J20: 1 | K20: 307
A21: Education | B21: 6780 | C21: 1655 | D21: 399 | E21: 3 | F21: 479 | G21: 0 | H21: 0 | I21: 33 | J21: 0 | K21: 9351
A22: Energy | B22: 209 | C22: 557 | D22: 0 | E22: 205 | F22: 13 | G22: 0 | H22: 0 | I22: 0 | J22: 0 | K22: 984
A23: Environment and Protected Areas | B23: 153 | C23: 96 | D23: 248 | E23: 52 | F23: 4 | G23: 0 | H23: 0 | I23: 0 | J23: 1 | K23: 554
A24: Executive Council | B24: 24 | C24: 11 | D24: 0 | E24: 0 | F24: 0 | G24: 0 | H24: 0 | I24: 0 | J24: 0 | K24: 35
A25: Forestry, Parks and Tourism | B25: 160 | C25: 179 | D25: 47 | E25: 11 | F25: 38 | G25: 1 | H25: 0 | I25: 0 | J25: 0 | K25: 435
A26: Health | B26: 9516 | C26: 7434 | D26: 7580 | E26: 89 | F26: 546 | G26: 1278 | H26: 0 | I26: 0 | J26: 3 | K26: 26446
... A42: Total 2023-24 Expense | B42: 23637 | C42: 16392 | D42: 16517 | E42: 2821 | F42: 2862 | G42: 1530 | H42: -322 | I42: 2848 | J42: 1997 | K42: 68282

Sheet Sch 24 Exp by Function
A1: Ministry Expense by Function
B3: Health | C3: Education | D3: Social Services | E3: Agriculture, Resource Management and Economic Development | F3: Protection of Persons and Property (includes contingency and disaster assistance) | G3: Transportation, Communications and Utilities | H3: Regional Planning and Development | I3: Environment | J3: Recreation and Culture | K3: Housing | L3: General Government (includes pension provisions) | N3: Total 2023-24 Expense
M6: Debt Servicing Costs
A14: Legislative Assembly | B14: 0 | C14: 0 | D14: 16 | E14: 0 | F14: 0 | G14: 0 | H14: 0 | I14: 0 | J14: 0 | K14: 0 | L14: 164 | M14: 0 | N14: 180
A16: Advanced Education | B16: 0 | C16: 6339 | D16: 0 | E16: 0 | F16: 0 | G16: 0 | H16: 0 | I16: 0 | J16: 0 | K16: 0 | L16: -25 | M16: 0 | N16: 6314
A17: Affordability and Utilities | B17: 0 | C17: 0 | D17: 0 | E17: 0 | F17: 0 | G17: 0 | H17: 0 | I17: 0 | J17: 0 | K17: 0 | L17: 140 | M17: 0 | N17: 140
A18: Agriculture and Irrigation | B18: 0 | C18: 0 | D18: 0 | E18: 843 | F18: 0 | G18: 0 | H18: 0 | I18: 49 | J18: 0 | K18: 0 | L18: 0 | M18: 0 | N18: 892
A19: Children's Services | B19: 0 | C19: 0 | D19: 2917 | E19: 0 | F19: 0 | G19: 0 | H19: 0 | I19: 0 | J19: 0 | K19: 0 | L19: 0 | M19: 0 | N19: 2917
A20: Culture | B20: 0 | C20: 0 | D20: 0 | E20: 20 | F20: 0 | G20: 0 | H20: 0 | I20: 0 | J20: 287 | K20: 0 | L20: 0 | M20: 0 | N20: 307
A21: Education | B21: 0 | C21: 9317 | D21: 0 | E21: 0 | F21: 0 | G21: 0 | H21: 0 | I21: 0 | J21: 0 | K21: 0 | L21: 0 | M21: 33 | N21: 9351
A22: Energy | B22: 0 | C22: 0 | D22: 0 | E22: 826 | F22: 0 | G22: 0 | H22: 0 | I22: 135 | J22: 0 | K22: 0 | L22: 22 | M22: 0 | N22: 984
A23: Environment and Protected Areas | B23: 0 | C23: 0 | D23: 0 | E23: 119 | F23: 0 | G23: 0 | H23: 0 | I23: 435 | J23: 0 | K23: 0 | L23: 0 | M23: 0 | N23: 554
A24: Executive Council | B24: 0 | C24: 0 | D24: 0 | E24: 14 | F24: 0 | G24: 0 | H24: 0 | I24: 0 | K24: 0 | L24: 21 | M24: 0 | N24: 35
A25: Forestry, Parks and Tourism | B25: 0 | C25: 0 | D25: 0 | E25: 211 | F25: 103 | G25: 0 | H25: 0 | I25: 0 | J25: 122 | K25: 0 | L25: 0 | M25: 0 | N25: 435
A26: Health | B26: 26446 | C26: 0 | D26: 0 | E26: 0 | F26: 0 | G26: 0 | H26: 0 | I26: 0 | J26: 0 | K26: 0 | L26: 0 | M26: 0 | N26: 26446
A27: Indigenous Relations | B27: 0 | C27: 0 | D27: 0 | E27: 9 | F27: 0 | G27: 0 | H27: 222 | I27: 0 | J27: 0 | K27: 0 | L27: 0 | M27: 0 | N27: 230
A28: Infrastructure | B28: 5 | C28: 1 | D28: 0 | E28: 0 | F28: 0 | G28: 2 | H28: 0 | I28: 24 | J28: 0 | K28: 1 | L28: 580 | M28: 0 | N28: 613
A29: Jobs, Economy and Northern Development | B29: 0 | C29: 100 | D29: 0 | E29: 188 | F29: 86 | G29: 0 | H29: 0 | I29: 0 | J29: 0 | K29: 0 | L29: 0 | M29: 0 | N29: 374
A30: Justice | B30: 0 | C30: 0 | D30: 135 | E30: 0 | F30: 524 | G30: 0 | H30: 0 | I30: 0 | J30: 0 | K30: 0 | L30: 0 | M30: 0 | N30: 658
A31: Mental Health and Addiction | B31: 166 | C31: 0 | D31: 0 | E31: 0 | F31: 0 | G31: 0 | H31: 0 | I31: 0 | J31: 0 | K31: 0 | L31: 0 | M31: 0 | N31: 166
A32: Municipal Affairs | B32: 0 | C32: 0 | D32: 0 | E32: 0 | F32: 28 | G32: 0 | H32: 880 | I32: 0 | J32: 69 | K32: 0 | L32: 36 | M32: 0 | N32: 1014
A33: Public Safety and Emergency Services | B33: 0 | C33: 0 | D33: 39 | E33: 0 | F33: 1177 | G33: 0 | H33: 0 | I33: 0 | J33: 0 | K33: 0 | L33: 0 | M33: 0 | N33: 1217
A34: Seniors, Community and Social Services | B34: 0 | C34: 92 | D34: 5109 | E34: 0 | F34: 0 | G34: 0 | H34: 0 | I34: 0 | J34: 0 | K34: 265 | L34: 0 | M34: 0 | N34: 5466
A35: Service Alberta and Red Tape Reduction | B35: 0 | C35: 0 | D35: 0 | E35: 0 | F35: 80 | G35: 0 | H35: 0 | I35: 0 | J35: 0 | K35: 0 | L35: 55 | M35: 0 | N35: 135
A36: Skilled Trades and Professions | B36: 0 | C36: 173 | D36: 0 | E36: 2 | F36: 0 | G36: 0 | H36: 0 | I36: 0 | J36: 0 | K36: 0 | L36: 0 | M36: 0 | N36: 175
... A40: Treasury Board and Finance | B40: 15 | C40: 11 | D40: 38 | E40: 54 | F40: 58 | G40: 0 | H40: 0 | I40: 2 | J40: 2 | K40: 0 | L40: 1568 | M40: 2714 | N40: 4460
A41: Contingency (voted in TBF) | B41: 0 | C41: 0 | D41: 0 | E41: 0 | F41: 1500 | G41: 0 | H41: 0 | I41: 0 | J41: 0 | K41: 0 | M41: 0 | N41: 1500
A42: Total 2023-24 Expense | B42: 26681 | C42: 16033 | D42: 8259 | E42: 2654 | F42: 3632 | G42: 2465 | H42: 1101 | I42: 657 | J42: 481 | K42: 266 | L42: 3205 | M42: 2848 | N42: 68282

Sheet Sch 25 Bud 22 Historical
A1: Historical Fiscal Summary, 2008-09 to 2025-26 a
A3: (millions of dollars)
C4: =1 -> 1 | D4: =C4+1 -> 2 | E4: =D4+1 -> 3 | F4: =E4+1 -> 4 | G4: =F4+1 -> 5 | H4: =G4+1 -> 6 | I4: =H4+1 -> 7 | J4: =I4+1 -> 8 | K4: =J4+1 -> 9 | ... M4: =L4+1 -> 11 | N4: 12 | O4: 13 | P4: =O4+1 -> 14 | Q4: =P4+1 -> 15 | R4: =Q4+1 -> 16 | S4: =R4+1 -> 17 | T4: =S4+1 -> 18
C6: 2008-09 | D6: 2009-10 | E6: 2010-11 | F6: 2011-12 | G6: 2012-13 | H6: 2013-14 | I6: 2014-15 | J6: 2015-16 | K6: 2016-17 | L6: 2017-18 | M6: 2018-19 | N6: 2019-20 | O6: 2020-21 | P6: 2021-22 | Q6: 2022-23 | R6: 2023-24 | S6: 2024-25 | T6: 2025-26
A7: Statement of Operations | P7: Actual | Q7: Forecast | R7: Estimate | S7: Target | T7: Target
B8: Revenue
A9: 1 | B9: Personal income tax | C9: 8708 | D9: 7877 | E9: 7631 | F9: 8563 | G9: 9621 | H9: 10537 | I9: 11042 | J9: 11357 | K9: 10763 | L9: 10775 | M9: 11874 | N9: 11244 | O9: 11257 | P9: =13335 -> 13335 | Q9: ='Sch 5 Revenue'!D6 -> 13806 | R9: ='Sch 5 Revenue'!E6 -> 14069 | S9: ='Sch 5 Revenue'!F6 -> 15034 | T9: ='Sch 5 Revenue'!G6 -> 16071
A10: 2 | B10: Corporate income tax | C10: 4252 | D10: 4754 | E10: 3334 | F10: 3678 | G10: 4756 | H10: 5488 | I10: 5796 | J10: 4195 | K10: 3769 | L10: 3448 | M10: 4871 | N10: 4107 | O10: 3037 | P10: =4718 -> 4718 | Q10: ='Sch 5 Revenue'!D7 -> 6413 | R10: ='Sch 5 Revenue'!E7 -> 5911 | S10: ='Sch 5 Revenue'!F7 -> 6254 | T10: ='Sch 5 Revenue'!G7 -> 6590
A11: 3 | B11: Other tax revenue | C11: =1466+2175+176 -> 3817 | D11: =1532+2029+185 -> 3746 | E11: =1589+2040+191 -> 3820 | F11: =1660+2241+198 -> 4099 | G11: =1776+2345+212 -> 4333 | H11: =1860+2439+201 -> 4500 | I11: =1888+2496+214 -> 4598 | J11: 5168 | K11: 5649 | L11: 6538 | M11: 6833 | N11: 5747 | O11: 5285 | P11: =5453 -> 5453 | Q11: ='Sch 5 Revenue'!D17 -> 4361 | R11: ='Sch 5 Revenue'!E17 -> 5012 | S11: ='Sch 5 Revenue'!F17 -> 5767 | T11: ='Sch 5 Revenue'!G17 -> 5948
A12: 4 | B12: Resource revenue | C12: 11915 | D12: 6768 | E12: 8428 | F12: 11636 | G12: =7622+157 -> 7779 | H12: 9578 | I12: 8948 | J12: 2789 | K12: 3097 | L12: 4980 | M12: 5429 | N12: 5937 | O12: 3091 | P12: =16170 -> 16170 | Q12: ='Sch 5 Revenue'!D24 -> 27544 | R12: ='Sch 5 Revenue'!E24 -> 18361 | S12: ='Sch 5 Revenue'!F24 -> 17284 | T12: ='Sch 5 Revenue'!G24 -> 15742
A13: 5 | B13: Investment income | C13: =-1917+29 -> -1888 | D13: 3541 | E13: 2486 | F13: =2059+109 -> 2168 | G13: =2493-3+105 -> 2595 | H13: =3225+198 -> 3423 | I13: 3113 | J13: 2544 | K13: 3698 | L13: 3126 | M13: 2349 | N13: 2828 | O13: 2643 | P13: =3579 -> 3579 | Q13: ='Sch 5 Revenue'!D41 -> 1035 | R13: ='Sch 5 Revenue'!E41 -> 3154 | S13: ='Sch 5 Revenue'!F41 -> 3273 | T13: ='Sch 5 Revenue'!G41 -> 3407
A14: 6 | B14: Premiums, fees and licences | C14: =2603+753 -> 3356 | D14: =1914+841+102 -> 2857 | E14: =1986+936 -> 2922 | F14: =1942+989 -> 2931 | G14: =2147+1037 -> 3184 | H14: 3437 | I14: 3564 | J14: 3574 | K14: 3701 | L14: 3839 | M14: 3911 | N14: 3929 | O14: 4021 | P14: =4520 -> 4520 | Q14: ='Sch 5 Revenue'!D57 -> 4796 | R14: ='Sch 5 Revenue'!E57 -> 5040 | S14: ='Sch 5 Revenue'!F57 -> 5289 | T14: ='Sch 5 Revenue'!G57 -> 5360
A15: 7 | B15: Other own-source revenue | C15: =3129+2211-753 -> 4587 | D15: =3209+2259-841 -> 4627 | E15: =3502+2337-936 -> 4903 | F15: =3724+2393-989 -> 5128 | G15: =3784+2487-1037 -> 5234 | H15: =2873+2541-2 -> 5412 | I15: =2665+3773 -> 6438 | J15: 5850 | K15: =543+3094 -> 3637 | L15: 6983 | M15: 6292 | N15: 3360 | O15: 3272 | P15: =8952 -> 8952 | Q15: ='Sch 5 Revenue'!D49+'Sch 5 Revenue'!D66 -> 6305 | R15: ='Sch 5 Revenue'!E49+'Sch 5 Revenue'!E66 -> 6554 | S15: ='Sch 5 Revenue'!F49+'Sch 5 Revenue'!F66 -> 6348 | T15: ='Sch 5 Revenue'!G49+'Sch 5 Revenue'!G66 -> 6377
A16: 8 | B16: Total own-source revenue | C16: =SUM(C9:C15) -> 34747 | D16: =SUM(D9:D15) -> 34170 | E16: =SUM(E9:E15) -> 33524 | F16: =SUM(F9:F15) -> 38203 | G16: =SUM(G9:G15) -> 37502 | H16: =SUM(H9:H15) -> 42375 | I16: =SUM(I9:I15) -> 43499 | J16: =SUM(J9:J15) -> 35477 | ... N16: =SUM(N9:N15) -> 37152 | O16: =SUM(O9:O15)-1 -> 32605 | P16: =SUM(P9:P15) -> 56727 | Q16: =SUM(Q9:Q15) -> 64260 | R16: =SUM(R9:R15) -> 58101 | S16: =SUM(S9:S15) -> 59249 | T16: =SUM(T9:T15) -> 59495
A17: 9 | B17: Federal transfers | C17: 4578 | D17: 5342 | E17: 5452 | F17: 5192 | G17: 5042 | H17: =5477+1582 -> 7059 | I17: 5982 | J17: 7142 | K17: 7979 | L17: 7606 | M17: 8013 | N17: 9072 | O17: 10532 | P17: =11595 -> 11595 | Q17: ='Sch 5 Revenue'!D34 -> 11765 | R17: ='Sch 5 Revenue'!E34 -> 12552 | S17: ='Sch 5 Revenue'!F34 -> 12475 | T17: ='Sch 5 Revenue'!G34 -> 13113
A18: 10 | B18: Total Revenue | C18: =C16+C17 -> 39325 | D18: =D16+D17 -> 39512 | E18: =E16+E17 -> 38976 | F18: =F16+F17 -> 43395 | G18: =G16+G17 -> 42544 | H18: =H16+H17 -> 49434 | I18: =I16+I17 -> 49481 | J18: =J16+J17 -> 42619 | ... T18: =T16+T17 -> 72608
B19: Expense by Function
A20: 11 | B20: Health | C20: 13674 | D20: 14636 | E20: 15393 | F20: 16284 | G20: 17254 | H20: 17967 | I20: 19366 | J20: 20115 | K20: 20687 | L20: 21239 | M20: 21921 | N20: 22408 | O20: 23984 | P20: =25131 -> 25131 | Q20: 24421 | R20: =26681 -> 26681 | S20: =27733 -> 27733 | T20: =28199 -> 28199
A21: 12 | B21: Basic / advanced education | C21: 10438 | D21: =10967+102-2 -> 11067 | E21: 11362 | F21: 11951 | G21: 12394 | H21: 12782 | I21: 13103 | J21: 13673 | K21: 14110 | L21: 14471 | M21: 14848 | N21: 14971 | O21: 14134 | P21: =14296 -> 14296 | Q21: 15360 | R21: =16033 -> 16033 | S21: =16335 -> 16335 | T21: =16601 -> 16601
A22: 13 | B22: Social services | C22: 3417 | D22: 3807 | E22: =4014+174-59 -> 4129 | F22: =4164+170-56 -> 4278 | G22: 4641 | H22: 4668 | I22: 4548 | J22: 4752 | K22: 5198 | L22: 5592 | M22: 5867 | N22: 6203 | O22: 5919 | P22: =5989 -> 5989 | Q22: 6961 | R22: =8259 -> 8259 | S22: =8059 -> 8059 | T22: =8443 -> 8443
A23: 14 | B23: Other program expense | C23: =37915-C20-C21-C22 -> 10386 | D23: =39344-D20-D21-D22 -> 9834 | E23: =40327-E20-E21-E22 -> 9443 | F23: =42366-F20-F21-F22 -> 9853 | G23: =44817-G20-G21-G22 -> 10528 | H23: =48387-H20-H21-H22 -> 12970 | I23: =48048-I20-I21-I22 -> 11031 | J23: =48915-J20-J21-J22 -> 10375 | K23: =52602-K20-K21-K22 -> 12607 | L23: =54491-L20-L21-L22 -> 13189 | M23: =54502-M20-M21-M22 -> 11866 | N23: =56475-N20-N21-N22 -> 12893 | O23: =57895-O20-O21-O22 -> 13858 | P23: =16686 -> 16686 | Q23: =63031-Q20-Q21-Q22 -> 16289 | R23: =65756-R20-R21-R22 -> 14783 | S23: =67218-S20-S21-S22 -> 15091 | T23: =68483-T20-T21-T22 -> 15240
A24: 15 | B24: Total program expense | C24: =C27-C26-C25 -> 37915 | D24: =D27-D26-D25 -> 39344 | E24: =E27-E26-E25 -> 40327 | F24: =F27-F26-F25 -> 42366 | G24: =G27-G26-G25 -> 44817 | H24: =H27-H26-H25 -> 48387 | I24: =I27-I26-I25 -> 48048 | J24: =J27-J26-J25 -> 48915 | ... T24: =T27-T26-T25 -> 68483
A25: 16 | B25: Debt servicing costs | C25: 208 | D25: 214 | E25: 472 | F25: 509 | G25: 530 | H25: 601 | I25: =370+352 -> 722 | J25: =323+452+1 -> 776 | K25: 1018 | L25: 1420 | M25: 1971 | N25: 2235 | O25: 2486 | P25: =2641 -> 2641 | Q25: ='Sch 10 Debt Serv Costs'!D25 -> 2715 | R25: ='Sch 10 Debt Serv Costs'!E25 -> 2848 | S25: ='Sch 10 Debt Serv Costs'!F25 -> 2805 | T25: ='Sch 10 Debt Serv Costs'!G25 -> 3103
A26: =A25+1 -> 17 | B26: Pension provisions | C26: 2133 | D26: =428+2 -> 430 | E26: 439 | F26: 634 | G26: 296 | H26: 748 | I26: -404 | J26: -630 | K26: -543 | L26: -593 | M26: -190 | N26: -334 | O26: -282 | P26: =-365 -> -365 | Q26: ='Sch 1 Cons Fisc Sum'!E15 -> -111 | R26: ='Sch 1 Cons Fisc Sum'!F15 -> -322 | S26: ='Sch 1 Cons Fisc Sum'!G15 -> -336 | T26: ='Sch 1 Cons Fisc Sum'!H15 -> -347
A27: =A26+1 -> 18 | B27: Total Expense | C27: 40256 | D27: 39988 | E27: =41064+174 -> 41238 | F27: =43339+170 -> 43509 | G27: 45643 | H27: 49736 | I27: 48366 | J27: 49061 | K27: 53077 | L27: 55318 | M27: 56283 | N27: 58376 | O27: 60099 | P27: =64378 -> 64378 | Q27: ='Sch 1 Cons Fisc Sum'!E17 -> 65635 | R27: ='Sch 1 Cons Fisc Sum'!F17 -> 68282 | S27: ='Sch 1 Cons Fisc Sum'!G17 -> 69687 | T27: ='Sch 1 Cons Fisc Sum'!H17 -> 71239
A28: =A27+1 -> 19 | B28: Surplus / (Deficit) | C28: =C18-C27 -> -931 | D28: =D18-D27 -> -476 | E28: =E18-E27 -> -2262 | F28: =F18-F27 -> -114 | G28: =G18-G27 -> -3099 | H28: =H18-H27 -> -302 | I28: =I18-I27 -> 1115 | J28: =J18-J27 -> -6442 | ... T28: =T18-T27 -> 1369
A29: Capital Plan b | C29: 7943 | D29: 8000 | E29: 7544 | F29: 6884 | G29: 6062 | H29: 5770 | I29: 6181 | J29: 6558 | K29: 6578 | L29: 9021 | M29: 6057 | N29: 5545 | O29: 6896 | P29: =6622 -> 6622 | Q29: ='Sch 1 Cons Fisc Sum'!E26 -> 6446 | R29: ='Sch 1 Cons Fisc Sum'!F26 -> 8005 | S29: ='Sch 1 Cons Fisc Sum'!G26 -> 7976 | T29: ='Sch 1 Cons Fisc Sum'!H26 -> 7008
A30: Statement of Financial Position (at March 31)
